<? xml version="1.0" ?>
<sdf version="1.4">

	<world name="default">

		<include>
			<uri>model://ground_plane</uri>
		</include>

		<include>
			<uri>model://sun</uri>
		</include>

		<model name = "stewart">
			<plugin name="joint_controller" filename="libjoint_controller.so"/>

			<joint name = "piston1_prismatic_joint" type = "prismatic" >
				<parent> piston1_cylinder_link </parent>
				<child> piston1_shaft_link </child>
				<pose> 0 0 0 0 0 0 </pose>
				<axis>
					<xyz> -0.9216132273888745 -0.38810959676599416 0.9814320398438321 </xyz>
					<limit>
						<lower> 0 </lower>
						<upper> 1.0189192520748789 </upper>
					</limit>
				</axis>
			</joint>

			<joint name = "piston2_prismatic_joint" type = "prismatic" >
				<parent> piston2_cylinder_link </parent>
				<child> piston2_shaft_link </child>
				<pose> 0 0 0 0 0 0 </pose>
				<axis> 
					<xyz> 0 0 1 </xyz>
					<limit>
						<lower> 0 </lower>
						<upper> 1.0189192520748789 </upper>
					</limit>
				</axis>
			</joint>

			<joint name = "piston3_prismatic_joint" type = "prismatic" >
				<parent> piston3_cylinder_link </parent>
				<child> piston3_shaft_link </child>
				<pose> 0 0 0 0 0 0 </pose>
				<axis>
					<xyz> 0 0 1 </xyz>
					<limit>
						<lower> 0 </lower>
						<upper> 1.0189192520748789 </upper>
					</limit>
				</axis>
			</joint>

			<joint name = "piston4_prismatic_joint" type = "prismatic" >
				<parent> piston4_cylinder_link </parent>
				<child> piston4_shaft_link </child>
				<pose> 0 0 0 0 0 0 </pose>
				<axis> 
					<xyz> 0 0 1 </xyz>
					<limit>
						<lower> 0 </lower>
						<upper> 1.0189192520748789 </upper>
					</limit>
				</axis>
			</joint>

			<joint name = "piston5_prismatic_joint" type = "prismatic" >
				<parent> piston5_cylinder_link </parent>
				<child> piston5_shaft_link </child>
				<pose> 0 0 0 0 0 0 </pose>
				<axis> 
					<xyz> 0 0 1 </xyz>
					<limit>
						<lower> 0 </lower>
						<upper> 1.0189192520748789 </upper>
					</limit>
				</axis>
			</joint>

			<joint name = "piston6_prismatic_joint" type = "prismatic" >
				<parent> piston6_cylinder_link </parent>
				<child> piston6_shaft_link </child>
				<pose> 0 0 0 0 0 0 </pose>
				<axis> 
					<xyz> 0 0 1 </xyz>
					<limit>
						<lower> 0 </lower>
						<upper> 1.0189192520748789 </upper>
					</limit>
				</axis>
			</joint>

			<joint name = "bottom_ball1_joint" type = "revolute" >
				<parent> base_link </parent>
				<child> bottom_ball1_link </child>
				<pose> 0 0 0 0 0 0 </pose>
				<axis> 
					<xyz> 0 0 1 </xyz>
					<limit>
						<lower> -1000000000000 </lower>
						<upper> 1000000000000 </upper>
					</limit>
				</axis>
			</joint>

			<joint name = "bottom_ball2_joint" type = "revolute" >
				<parent> base_link </parent>
				<child> bottom_ball2_link </child>
				<pose> 0 0 0 0 0 0 </pose>
				<axis> 
					<xyz> 0 0 1 </xyz>
					<limit>
						<lower> -1000000000000 </lower>
						<upper> 1000000000000 </upper>
					</limit>
				</axis>
			</joint>

			<joint name = "bottom_ball3_joint" type = "revolute" >
				<parent> base_link </parent>
				<child> bottom_ball3_link </child>
				<pose> 0 0 0 0 0 0 </pose>
				<axis> 
					<xyz> 0 0 1 </xyz>
					<limit>
						<lower> -1000000000000 </lower>
						<upper> 1000000000000 </upper>
					</limit>
				</axis>
			</joint>

			<joint name = "bottom_ball4_joint" type = "revolute" >
				<parent> base_link </parent>
				<child> bottom_ball4_link </child>
				<pose> 0 0 0 0 0 0 </pose>
				<axis> 
					<xyz> 0 0 1 </xyz>
					<limit>
						<lower> -1000000000000 </lower>
						<upper> 1000000000000 </upper>
					</limit>
				</axis>
			</joint>

			<joint name = "bottom_ball5_joint" type = "revolute" >
				<parent> base_link </parent>
				<child> bottom_ball5_link </child>
				<pose> 0 0 0 0 0 0 </pose>
				<axis> 
					<xyz> 0 0 1 </xyz>
					<limit>
						<lower> -1000000000000 </lower>
						<upper> 1000000000000 </upper>
					</limit>
				</axis>
			</joint>

			<joint name = "bottom_ball6_joint" type = "revolute" >
				<parent> base_link </parent>
				<child> bottom_ball6_link </child>
				<pose> 0 0 0 0 0 0 </pose>
				<axis> 
					<xyz> 0 0 1 </xyz>
					<limit>
						<lower> -1000000000000 </lower>
						<upper> 1000000000000 </upper>
					</limit>
				</axis>
			</joint>

			<joint name = "piston1_pitch_joint" type = "revolute" >
				<parent> bottom_ball1_link </parent>
				<child> piston1_cylinder_link </child>
				<pose> 0 0 -1.0189192520748789 0 0 0 </pose>
				<axis> 
					<xyz> -0.9216132273888745 0.38810959676599416 0 </xyz>
					<limit>
						<lower> -6.283 </lower>
						<upper> 6.283 </upper>
					</limit>
				</axis>
			</joint>

			<joint name = "piston2_pitch_joint" type = "revolute" >
				<parent> bottom_ball2_link </parent>
				<child> piston2_cylinder_link </child>
				<pose> 0 0 -1.0189192520748789 0 0 0</pose>
				<axis> 
					<xyz> 0.9217712459733655 0.3877341487368754 0 </xyz>
					<limit>
						<lower> -6.283 </lower>
						<upper> 6.283 </upper>
					</limit>
				</axis>
			</joint>

			<joint name = "piston3_pitch_joint" type = "revolute" >
				<parent> bottom_ball3_link </parent>
				<child> piston3_cylinder_link </child>
				<pose> 0 0 -1.0189192520748789 0 0 0 </pose>
				<axis> 
					<xyz> 1 0 0 </xyz>
					<limit>
						<lower> -6.283 </lower>
						<upper> 6.283 </upper>
					</limit>
				</axis>
			</joint>

			<joint name = "piston4_pitch_joint" type = "revolute" >
				<parent> bottom_ball4_link </parent>
				<child> piston4_cylinder_link </child>
				<pose> 0 0 -1.0189192520748789 0 0 0 </pose>
				<axis> 
					<xyz> -0.9216132273888745 0.38810959676599416 0 </xyz>
					<limit>
						<lower> -6.283 </lower>
						<upper> 6.283 </upper>
					</limit>
				</axis>
			</joint>

			<joint name = "piston5_pitch_joint" type = "revolute" >
				<parent> bottom_ball5_link </parent>
				<child> piston5_cylinder_link </child>
				<pose> 0 0 -1.0189192520748789 0 0 0 </pose>
				<axis> 
					<xyz> 0.9217712459733655 0.3877341487368754 0 </xyz>
					<limit>
						<lower> -6.283 </lower>
						<upper> 6.283 </upper>
					</limit>
				</axis>
			</joint>

			<joint name = "piston6_pitch_joint" type = "revolute" >
				<parent> bottom_ball6_link </parent>
				<child> piston6_cylinder_link </child>
				<pose> 0 0 -1.0189192520748789 0 0 0 </pose>
				<axis> 
					<xyz> 1 0 0 </xyz>
					<limit>
						<lower> -6.283 </lower>
						<upper> 6.283 </upper>
					</limit>
				</axis>
			</joint>

			<link name = "base_link" >
				<pose> 0 0 0.125 0 0 0 </pose>
				<inertial>
					<mass> 10.0 </mass>
					<inertia>
						<ixx> 2.552083333333333 </ixx>
						<ixy> 0.0 </ixy>
						<ixz> 0.0</ixz>
						<iyy> 2.552083333333333 </iyy>
						<iyz> 0.0 </iyz>
						<izz> 5.0 </izz>
					</inertia>
				</inertial>

				<visual name = "base_link_visual" >
					<geometry>
						<cylinder>
							<radius> 1.0 </radius>
							<length> 0.25 </length>
						</cylinder>
					</geometry>
				</visual>

				<collision name = "base_link_collision" >
					<geometry>
						<cylinder>
							<radius> 1.0 </radius>
							<length> 0.25 </length>
						</cylinder>
					</geometry>
				</collision>
			</link>

			<link name = "bottom_ball1_link" >
				<pose> -0.10094113843523252 0.7998817953744161 0.25 0 0 0 </pose>
				<inertial>
					<mass> 0.1 </mass>
					<inertia>
						<ixx> 0.0 </ixx>
						<ixy> 0.0 </ixy>
						<ixz> 0.0 </ixz>
						<iyy> 0.0 </iyy>
						<iyz> 0.0 </iyz>
						<izz> 0.0 </izz>
					</inertia>
				</inertial>

				<visual name = "bottom_ball1_link_visual" >
					<geometry>
						<sphere>
							<radius> 0.1" </radius>
						</sphere>
					</geometry>
				</visual>

				<collision name = "bottom_ball1_link_collision" >
					<geometry>
						<sphere>
							<radius> 0.1" </radius>
						</sphere>
					</geometry>
				</collision>
			</link>

			<link name = "bottom_ball2_link" >
				<pose> 0.10061530109167109 0.7999228470210314 0.25 0 0 0 </pose>
				<inertial>
					<mass> 0.1 </mass>
					<inertia>
						<ixx> 0.0 </ixx>
						<ixy> 0.0 </ixy>
						<ixz> 0.0 </ixz>
						<iyy> 0.0 </iyy>
						<iyz> 0.0 </iyz>
						<izz> 0.0 </izz>
					</inertia>
				</inertial>

				<visual name = "bottom_ball2_link_visual" >
					<geometry>
						<sphere>
							<radius> 0.1" </radius>
						</sphere>
					</geometry>
				</visual>

				<collision name = "bottom_ball2_link_collision" >
					<geometry>
						<sphere>
							<radius> 0.1" </radius>
						</sphere>
					</geometry>
				</collision>
			</link>

			<link name = "bottom_ball3_link" >
				<pose> 0.7429993434805581 -0.3129728032712424 0.25 0 0 0 </pose>
				<inertial>
					<mass> 0.1 </mass>
					<inertia>
						<ixx> 0.0 </ixx>
						<ixy> 0.0 </ixy>
						<ixz> 0.0 </ixz>
						<iyy> 0.0 </iyy>
						<iyz> 0.0 </iyz>
						<izz> 0.0 </izz>
					</inertia>
				</inertial>

				<visual name = "bottom_ball3_link_visual" >
					<geometry>
						<sphere>
							<radius> 0.1" </radius>
						</sphere>
					</geometry>
				</visual>

				<collision name = "bottom_ball3_link_collision" >
					<geometry>
						<sphere>
							<radius> 0.1" </radius>
						</sphere>
					</geometry>
				</collision>
			</link>

			<link name = "bottom_ball4_link" >
				<pose> 0.6421510948171859 -0.4874853550878114 0.25 0 0 0 </pose>
				<inertial>
					<mass> 0.1 </mass>
					<inertia>
						<ixx> 0.0 </ixx>
						<ixy> 0.0 </ixy>
						<ixz> 0.0 </ixz>
						<iyy> 0.0 </iyy>
						<iyz> 0.0 </iyz>
						<izz> 0.0 </izz>
					</inertia>
				</inertial>

				<visual name = "bottom_ball4_link_visual" >
					<geometry>
						<sphere>
							<radius> 0.1" </radius>
						</sphere>
					</geometry>
				</visual>

				<collision name = "bottom_ball4_link_collision" >
					<geometry>
						<sphere>
							<radius> 0.1" </radius>
						</sphere>
					</geometry>
				</collision>
			</link>

			<link name = "bottom_ball5_link" >
				<pose> -0.6433227790696778 -0.48593806388269956 0.25 0 0 0 </pose>
				<inertial>
					<mass> 0.1 </mass>
					<inertia>
						<ixx> 0.0 </ixx>
						<ixy> 0.0 </ixy>
						<ixz> 0.0 </ixz>
						<iyy> 0.0 </iyy>
						<iyz> 0.0 </iyz>
						<izz> 0.0 </izz>
					</inertia>
				</inertial>

				<visual name = "bottom_ball5_link_visual" >
					<geometry>
						<sphere>
							<radius> 0.1" </radius>
						</sphere>
					</geometry>
				</visual>

				<collision name = "bottom_ball5_link_collision" >
					<geometry>
						<sphere>
							<radius> 0.1" </radius>
						</sphere>
					</geometry>
				</collision>
			</link>

			<link name = "bottom_ball6_link" >
				<pose> -0.743750623750048 -0.31118324130874175 0.25 0 0 0 </pose>
				<inertial>
					<mass> 0.1 </mass>
					<inertia>
						<ixx> 0.0 </ixx>
						<ixy> 0.0 </ixy>
						<ixz> 0.0 </ixz>
						<iyy> 0.0 </iyy>
						<iyz> 0.0 </iyz>
						<izz> 0.0 </izz>
					</inertia>
				</inertial>

				<visual name = "bottom_ball6_link_visual" >
					<geometry>
						<sphere>
							<radius> 0.1" </radius>
						</sphere>
					</geometry>
				</visual>

				<collision name = "bottom_ball6_link_collision" >
					<geometry>
						<sphere>
							<radius> 0.1" </radius>
						</sphere>
					</geometry>
				</collision>
			</link>

			<link name = "piston1_cylinder_link" >
				<pose> -0.39271479076532384 0.6764456008174773 1.25 -0.193209931693324 0 1.9691721688319346 </pose>
				<inertial>
					<mass> 0.1 </mass>
					<inertia>
						<ixx> 0.0 </ixx>
						<ixy> 0.0 </ixy>
						<ixz> 0.0 </ixz>
						<iyy> 0.0 </iyy>
						<iyz> 0.0 </iyz>
						<izz> 0.0 </izz>
					</inertia>
				</inertial>

				<visual name = "piston1_cylinder_link_visual" >
					<geometry>
						<cylinder>
							<radius> 0.1 </radius>
							<length> 2.0378385041497578" </length>
						</cylinder>
					</geometry>
				</visual>

				<collision name = "piston1_link_collision" >
					<geometry>
						<cylinder>
							<radius> 0.1 </radius>
							<length> 2.0378385041497578" </length>
						</cylinder>
					</geometry>
				</collision>
			</link>

			<link name = "piston2_cylinder_link" >
				<pose> 0.39271479076532384 0.6764456008174773 1.25 -0.193209931693324 0 -1.9691721688319346 </pose>
				<inertial>
					<mass> 0.1 </mass>
					<inertia>
						<ixx> 0.0 </ixx>
						<ixy> 0.0 </ixy>
						<ixz> 0.0 </ixz>
						<iyy> 0.0 </iyy>
						<iyz> 0.0 </iyz>
						<izz> 0.0 </izz>
					</inertia>
				</inertial>

				<visual name = "piston2_cylinder_link_visual" >
					<geometry>
						<cylinder>
							<radius> 0.1 </radius>
							<length> 2.0378385041497578" </length>
						</cylinder>
					</geometry>
				</visual>

				<collision name = "piston2_link_collision" >
					<geometry>
						<cylinder>
							<radius> 0.1 </radius>
							<length> 2.0378385041497578" </length>
						</cylinder>
					</geometry>
				</collision>
			</link>

			<link name = "piston3_cylinder_link" >
				<pose> 0.7821787249415378 0 1.25 -0.193209931693324 0 0 </pose>
				<inertial>
					<mass> 0.1 </mass>
					<inertia>
						<ixx> 0.0 </ixx>
						<ixy> 0.0 </ixy>
						<ixz> 0.0 </ixz>
						<iyy> 0.0 </iyy>
						<iyz> 0.0 </iyz>
						<izz> 0.0 </izz>
					</inertia>
				</inertial>

				<visual name = "piston3_cylinder_link_visual" >
					<geometry>
						<cylinder>
							<radius> 0.1 </radius>
							<length> 2.0378385041497578" </length>
						</cylinder>
					</geometry>
				</visual>

				<collision name = "piston3_link_collision" >
					<geometry>
						<cylinder>
							<radius> 0.1 </radius>
							<length> 2.0378385041497578" </length>
						</cylinder>
					</geometry>
				</collision>
			</link>

			<link name = "piston4_cylinder_link" >
				<pose> 0.3912231733809751 -0.6773093727100559 1.25 -0.193209931693324 0 1.9691721688319346 </pose>
				<inertial>
					<mass> 0.1 </mass>
					<inertia>
						<ixx> 0.0 </ixx>
						<ixy> 0.0 </ixy>
						<ixz> 0.0 </ixz>
						<iyy> 0.0 </iyy>
						<iyz> 0.0 </iyz>
						<izz> 0.0 </izz>
					</inertia>
				</inertial>

				<visual name = "piston4_cylinder_link_visual" >
					<geometry>
						<cylinder>
							<radius> 0.1 </radius>
							<length> 2.0378385041497578" </length>
						</cylinder>
					</geometry>
				</visual>

				<collision name = "piston4_link_collision" >
					<geometry>
						<cylinder>
							<radius> 0.1 </radius>
							<length> 2.0378385041497578" </length>
						</cylinder>
					</geometry>
				</collision>
			</link>

			<link name = "piston5_cylinder_link" >
				<pose> -0.3908216948670614 -0.6775411135661122 1.25 -0.193209931693324 0 -1.9691721688319346 </pose>
				<inertial>
					<mass> 0.1 </mass>
					<inertia>
						<ixx> 0.0 </ixx>
						<ixy> 0.0 </ixy>
						<ixz> 0.0 </ixz>
						<iyy> 0.0 </iyy>
						<iyz> 0.0 </iyz>
						<izz> 0.0 </izz>
					</inertia>
				</inertial>

				<visual name = "piston5_cylinder_link_visual" >
					<geometry>
						<cylinder>
							<radius> 0.1 </radius>
							<length> 2.0378385041497578" </length>
						</cylinder>
					</geometry>
				</visual>

				<collision name = "piston5_link_collision" >
					<geometry>
						<cylinder>
							<radius> 0.1 </radius>
							<length> 2.0378385041497578" </length>
						</cylinder>
					</geometry>
				</collision>
			</link>

			<link name = "piston6_cylinder_link" >
				<pose> -0.7821787249415378 0 1.25 -0.193209931693324 0 0 </pose>
				<inertial>
					<mass> 0.1 </mass>
					<inertia>
						<ixx> 0.0 </ixx>
						<ixy> 0.0 </ixy>
						<ixz> 0.0 </ixz>
						<iyy> 0.0 </iyy>
						<iyz> 0.0 </iyz>
						<izz> 0.0 </izz>
					</inertia>
				</inertial>

				<visual name = "piston6_cylinder_link_visual" >
					<geometry>
						<cylinder>
							<radius> 0.1 </radius>
							<length> 2.0378385041497578" </length>
						</cylinder>
					</geometry>
				</visual>

				<collision name = "piston6_link_collision" >
					<geometry>
						<cylinder>
							<radius> 0.1 </radius>
							<length> 2.0378385041497578" </length>
						</cylinder>
					</geometry>
				</collision>
			</link>

			<link name = "piston1_shaft_link" >
				<pose> -0.39271479076532384 0.6764456008174773 1.25 -0.193209931693324 0 1.9691721688319346 </pose>
				<inertial>
					<mass> 0.1 </mass>
					<inertia>
						<ixx> 0.0 </ixx>
						<ixy> 0.0 </ixy>
						<ixz> 0.0 </ixz>
						<iyy> 0.0 </iyy>
						<iyz> 0.0 </iyz>
						<izz> 0.0 </izz>
					</inertia>
				</inertial>

				<visual name = "piston1_shaft_visual" >
					<geometry>
						<cylinder>
							<radius> 0.05" </radius>
							<length> 2.0378385041497578" </length>
						</cylinder>>
					</geometry>
				</visual>

				<collision name = "piston1_shaft_collision" >
					<geometry>
						<cylinder>
							<radius> 0.05" </radius>
							<length> 2.0378385041497578" </length>
						</cylinder>>
					</geometry>
				</collision>
			</link>

			<link name = "piston2_shaft_link" >
				<pose> 0.39271479076532384 0.6764456008174773 1.25 -0.193209931693324 0 -1.9691721688319346 </pose>
				<inertial>
					<mass> 0.1 </mass>
					<inertia>
						<ixx> 0.0 </ixx>
						<ixy> 0.0 </ixy>
						<ixz> 0.0 </ixz>
						<iyy> 0.0 </iyy>
						<iyz> 0.0 </iyz>
						<izz> 0.0 </izz>
					</inertia>
				</inertial>

				<visual name = "piston2_shaft_visual" >
					<geometry>
						<cylinder>
							<radius> 0.05" </radius>
							<length> 2.0378385041497578" </length>
						</cylinder>>
					</geometry>
				</visual>

				<collision name = "piston2_shaft_collision" >
					<geometry>
						<cylinder>
							<radius> 0.05" </radius>
							<length> 2.0378385041497578" </length>
						</cylinder>>
					</geometry>
				</collision>
			</link>

			<link name = "piston3_shaft_link" >
				<pose> 0.7821787249415378 0 1.25 -0.193209931693324 0 0 </pose>
				<inertial>
					<mass> 0.1 </mass>
					<inertia>
						<ixx> 0.0 </ixx>
						<ixy> 0.0 </ixy>
						<ixz> 0.0 </ixz>
						<iyy> 0.0 </iyy>
						<iyz> 0.0 </iyz>
						<izz> 0.0 </izz>
					</inertia>
				</inertial>

				<visual name = "piston3_shaft_visual" >
					<geometry>
						<cylinder>
							<radius> 0.05" </radius>
							<length> 2.0378385041497578" </length>
						</cylinder>>
					</geometry>
				</visual>

				<collision name = "piston3_shaft_collision" >
					<geometry>
						<cylinder>
							<radius> 0.05" </radius>
							<length> 2.0378385041497578" </length>
						</cylinder>>
					</geometry>
				</collision>
			</link>

			<link name = "piston4_shaft_link" >
				<pose> 0.3912231733809751 -0.6773093727100559 1.25 -0.193209931693324 0 1.9691721688319346 </pose>
				<inertial>
					<mass> 0.1 </mass>
					<inertia>
						<ixx> 0.0 </ixx>
						<ixy> 0.0 </ixy>
						<ixz> 0.0 </ixz>
						<iyy> 0.0 </iyy>
						<iyz> 0.0 </iyz>
						<izz> 0.0 </izz>
					</inertia>
				</inertial>

				<visual name = "piston4_shaft_visual" >
					<geometry>
						<cylinder>
							<radius> 0.05" </radius>
							<length> 2.0378385041497578" </length>
						</cylinder>>
					</geometry>
				</visual>

				<collision name = "piston4_shaft_collision" >
					<geometry>
						<cylinder>
							<radius> 0.05" </radius>
							<length> 2.0378385041497578" </length>
						</cylinder>>
					</geometry>
				</collision>
			</link>

			<link name = "piston5_shaft_link" >
				<pose> -0.3908216948670614 -0.6775411135661122 1.25 -0.193209931693324 0 -1.9691721688319346 </pose>
				<inertial>
					<mass> 0.1 </mass>
					<inertia>
						<ixx> 0.0 </ixx>
						<ixy> 0.0 </ixy>
						<ixz> 0.0 </ixz>
						<iyy> 0.0 </iyy>
						<iyz> 0.0 </iyz>
						<izz> 0.0 </izz>
					</inertia>
				</inertial>

				<visual name = "piston5_shaft_visual" >
					<geometry>
						<cylinder>
							<radius> 0.05" </radius>
							<length> 2.0378385041497578" </length>
						</cylinder>>
					</geometry>
				</visual>

				<collision name = "piston5_shaft_collision" >
					<geometry>
						<cylinder>
							<radius> 0.05" </radius>
							<length> 2.0378385041497578" </length>
						</cylinder>>
					</geometry>
				</collision>
			</link>

			<link name = "piston6_shaft_link" >
				<pose> -0.7821787249415378 0 1.25 -0.193209931693324 0 0 </pose>
				<inertial>
					<mass> 0.1 </mass>
					<inertia>
						<ixx> 0.0 </ixx>
						<ixy> 0.0 </ixy>
						<ixz> 0.0 </ixz>
						<iyy> 0.0 </iyy>
						<iyz> 0.0 </iyz>
						<izz> 0.0 </izz>
					</inertia>
				</inertial>

				<visual name = "piston6_shaft_visual" >
					<geometry>
						<cylinder>
							<radius> 0.05" </radius>
							<length> 2.0378385041497578" </length>
						</cylinder>>
					</geometry>
				</visual>

				<collision name = "piston6_shaft_collision" >
					<geometry>
						<cylinder>
							<radius> 0.05" </radius>
							<length> 2.0378385041497578" </length>
						</cylinder>>
					</geometry>
				</collision>
			</link>

		</model>

	</world>

</sdf>