<? xml version = "1.0" ?>
<%
	BASE_HEIGHT = 0.25
	BASE_RADIUS = 1.0
	BASE_MASS = 10.0

	PLATFORM_HEIGHT = 0.1
	PLATFORM_RADIUS = BASE_RADIUS

	BALL_RADIUS = 0.1

	BASE_PLATFORM_DISTANCE = 2
	
	PISTON_RADIUS = BALL_RADIUS

	BALL_SEPARATION = 2*BASE_RADIUS**2-8*BASE_RADIUS*BALL_RADIUS+10*BALL_RADIUS**2-(2*BASE_RADIUS**2-8*BASE_RADIUS*BALL_RADIUS+10*BALL_RADIUS**2)*Math.cos(1.047-Math.asin(BALL_RADIUS/(BASE_RADIUS-2*BALL_RADIUS)))
	BALL_DTC = Math.sqrt(BASE_RADIUS**2-4*BASE_RADIUS*BALL_RADIUS+5*BALL_RADIUS**2)

	PISTON_PITCH_ANGLE = 1.571-Math.atan(BASE_PLATFORM_DISTANCE/BALL_SEPARATION)
	PISTON_YAW_ANGLE = 1.571-0.5*(3.142-(1.047-2*Math.asin(BALL_RADIUS/(BASE_RADIUS-2*BALL_RADIUS))))

	PISTON_LENGTH = Math.sqrt(BASE_PLATFORM_DISTANCE**2+BALL_SEPARATION**2)
%>
<robot name= "stewart" >
	<joint name = "bottom_ball1_joint" type = "continuous" >
		<parent link = "base_link" />
		<child link = "bottom_ball1_link" />
		<origin xyz = "<%= BALL_DTC*Math.cos(1.571+Math.asin(PISTON_RADIUS/(BASE_RADIUS-2*PISTON_RADIUS))) %> <%= BALL_DTC*Math.sin(1.571+Math.asin(PISTON_RADIUS/(BASE_RADIUS-2*PISTON_RADIUS))) %> <%= BASE_HEIGHT %>" rpy = "0 0 0" />
		<axis xyz = "0 0 1" />
	</joint>

	<joint name = "bottom_ball2_joint" type = "continuous" >
		<parent link = "base_link" />
		<child link = "bottom_ball2_link" />
		<origin xyz = "<%= BALL_DTC*Math.cos(1.571-Math.asin(PISTON_RADIUS/(BASE_RADIUS-2*PISTON_RADIUS))) %> <%= BALL_DTC*Math.sin(1.571-Math.asin(PISTON_RADIUS/(BASE_RADIUS-2*PISTON_RADIUS))) %> <%= BASE_HEIGHT %>" rpy = "0 0 0" />
		<axis xyz = "0 0 1" />
	</joint>

	<joint name = "bottom_ball3_joint" type = "continuous" >
		<parent link = "base_link" />
		<child link = "bottom_ball3_link" />
		<origin xyz = "<%= BALL_DTC*Math.cos(-0.524+Math.asin(PISTON_RADIUS/(BASE_RADIUS-2*PISTON_RADIUS))) %> <%= BALL_DTC*Math.sin(-0.524+Math.asin(PISTON_RADIUS/(BASE_RADIUS-2*PISTON_RADIUS))) %> <%= BASE_HEIGHT %>" rpy = "0 0 0" />
		<axis xyz = "0 0 1" />
	</joint>

	<joint name = "bottom_ball4_joint" type = "continuous" >
		<parent link = "base_link" />
		<child link = "bottom_ball4_link" />
		<origin xyz = "<%= BALL_DTC*Math.cos(-0.524-Math.asin(PISTON_RADIUS/(BASE_RADIUS-2*PISTON_RADIUS))) %> <%= BALL_DTC*Math.sin(-0.524-Math.asin(PISTON_RADIUS/(BASE_RADIUS-2*PISTON_RADIUS))) %> <%= BASE_HEIGHT %>" rpy = "0 0 0" />
		<axis xyz = "0 0 1" />
	</joint>

	<joint name = "bottom_ball5_joint" type = "continuous" >
		<parent link = "base_link" />
		<child link = "bottom_ball5_link" />
		<origin xyz = "<%= BALL_DTC*Math.cos(-2.62+Math.asin(PISTON_RADIUS/(BASE_RADIUS-2*PISTON_RADIUS))) %> <%= BALL_DTC*Math.sin(-2.62+Math.asin(PISTON_RADIUS/(BASE_RADIUS-2*PISTON_RADIUS))) %> <%= BASE_HEIGHT %>" rpy = "0 0 0" />
		<axis xyz = "0 0 1" />
	</joint>

	<joint name = "bottom_ball6_joint" type = "continuous" >
		<parent link = "base_link" />
		<child link = "bottom_ball6_link" />
		<origin xyz = "<%= BALL_DTC*Math.cos(-2.62-Math.asin(PISTON_RADIUS/(BASE_RADIUS-2*PISTON_RADIUS))) %> <%= BALL_DTC*Math.sin(-2.62-Math.asin(PISTON_RADIUS/(BASE_RADIUS-2*PISTON_RADIUS))) %> <%= BASE_HEIGHT %>" rpy = "0 0 0" />
		<axis xyz = "0 0 1" />
	</joint>

	<joint name = "piston1_pitch_joint" type = "continuous" >
		<parent link = "bottom_ball1_link" />
		<child link = "piston1_cylinder_link" />
		<origin xyz = "0 0 0" rpy = "<%= -PISTON_PITCH_ANGLE %> 0 <%= (1.571+Math.asin(PISTON_RADIUS/(BASE_RADIUS-2*PISTON_RADIUS)))+PISTON_YAW_ANGLE %>" />
		<axis xyz = "1 0 0" />
	</joint>

	<joint name = "piston2_pitch_joint" type = "continuous" >
		<parent link = "bottom_ball2_link" />
		<child link = "piston2_cylinder_link" />
		<origin xyz = "0 0 0" rpy = "<%= PISTON_PITCH_ANGLE %> 0 <%= (1.571-Math.asin(PISTON_RADIUS/(BASE_RADIUS-2*PISTON_RADIUS)))-PISTON_YAW_ANGLE %>" />
		<axis xyz = "1 0 0" />
	</joint>

	<joint name = "piston3_pitch_joint" type = "continuous" >
		<parent link = "bottom_ball3_link" />
		<child link = "piston3_cylinder_link" />
		<origin xyz = "0 0 0" rpy = "<%= -PISTON_PITCH_ANGLE %> 0 <%= (-0.349+Math.asin(PISTON_RADIUS/(BASE_RADIUS-2*PISTON_RADIUS)))+PISTON_YAW_ANGLE %>" />
		<axis xyz = "1 0 0" />
	</joint>

	<joint name = "piston4_pitch_joint" type = "continuous" >
		<parent link = "bottom_ball4_link" />
		<child link = "piston4_cylinder_link" />
		<origin xyz = "0 0 0" rpy = "<%= PISTON_PITCH_ANGLE %> 0 <%= (-0.349-Math.asin(PISTON_RADIUS/(BASE_RADIUS-2*PISTON_RADIUS)))-PISTON_YAW_ANGLE %>" />
		<axis xyz = "1 0 0" />
	</joint>

	<joint name = "piston5_pitch_joint" type = "continuous" >
		<parent link = "bottom_ball5_link" />
		<child link = "piston5_cylinder_link" />
		<origin xyz = "0 0 0" rpy = "<%= -PISTON_PITCH_ANGLE %> 0 <%= (-2.62+Math.asin(PISTON_RADIUS/(BASE_RADIUS-2*PISTON_RADIUS)))+PISTON_YAW_ANGLE %>" />
		<axis xyz = "1 0 0" />
	</joint>

	<joint name = "piston6_pitch_joint" type = "continuous" >
		<parent link = "bottom_ball6_link" />
		<child link = "piston6_cylinder_link" />
		<origin xyz = "0 0 0" rpy = "<%= PISTON_PITCH_ANGLE %> 0 <%= (-2.62-Math.asin(PISTON_RADIUS/(BASE_RADIUS-2*PISTON_RADIUS)))-PISTON_YAW_ANGLE %>" />
		<axis xyz = "1 0 0" />
	</joint>

	<joint name = "piston1_prismatic_joint" type = "prismatic" >
		<parent link = "piston1_cylinder_link" />
		<child link = "piston1_shaft_link" />
		<origin xyz = "0 0 <%= 0.75*PISTON_LENGTH %>" rpy = "0 0 0" />
		<axis xyz = "0 0 1" />
		<limit effort= "10" velocity= "1" lower = "0" upper = "<%= 0.5*PISTON_LENGTH %>" />
	</joint>

	<joint name = "piston2_prismatic_joint" type = "prismatic" >
		<parent link = "piston2_cylinder_link" />
		<child link = "piston2_shaft_link" />
		<origin xyz = "0 0 <%= 0.75*PISTON_LENGTH %>" rpy = "0 0 0" />
		<axis xyz = "0 0 1" />
		<limit effort= "10" velocity= "10" lower = "0" upper = "<%= 0.5*PISTON_LENGTH %>" />
	</joint>

	<joint name = "piston3_prismatic_joint" type = "prismatic" >
		<parent link = "piston3_cylinder_link" />
		<child link = "piston3_shaft_link" />
		<origin xyz = "0 0 <%= 0.75*PISTON_LENGTH %>" rpy = "0 0 0" />
		<axis xyz = "0 0 1" />
		<limit effort= "10" velocity= "10" lower = "0" upper = "<%= 0.5*PISTON_LENGTH %>" />
	</joint>

	<joint name = "piston4_prismatic_joint" type = "prismatic" >
		<parent link = "piston4_cylinder_link" />
		<child link = "piston4_shaft_link" />
		<origin xyz = "0 0 <%= 0.75*PISTON_LENGTH %>" rpy = "0 0 0" />
		<axis xyz = "0 0 1" />
		<limit effort= "10" velocity= "10" lower = "0" upper = "<%= 0.5*PISTON_LENGTH %>" />
	</joint>

	<joint name = "piston5_prismatic_joint" type = "prismatic" >
		<parent link = "piston5_cylinder_link" />
		<child link = "piston5_shaft_link" />
		<origin xyz = "0 0 <%= 0.75*PISTON_LENGTH %>" rpy = "0 0 0" />
		<axis xyz = "0 0 1" />
		<limit effort= "10" velocity= "10" lower = "0" upper = "<%= 0.5*PISTON_LENGTH %>" />
	</joint>

	<joint name = "piston6_prismatic_joint" type = "prismatic" >
		<parent link = "piston6_cylinder_link" />
		<child link = "piston6_shaft_link" />
		<origin xyz = "0 0 <%= 0.75*PISTON_LENGTH %>" rpy = "0 0 0" />
		<axis xyz = "0 0 1" />
		<limit effort= "10" velocity= "10" lower = "0" upper = "<%= 0.5*PISTON_LENGTH %>" />
	</joint>

  	<transmission name="piston1_transmission">
    	<type> transmission_interface/SimpleTransmission </type>
    	<joint name="piston1_prismatic_joint">
      		<hardwareInterface> hardware_interface/PositionJointInterface </hardwareInterface>
    	</joint>
    	<actuator name= "piston1_motor">
      		<hardwareInterface> PositionJointInterface </hardwareInterface>
      		<mechanicalReduction> 1 </mechanicalReduction>
    	</actuator>
  	</transmission>

  	<transmission name="piston2_transmission">
    	<type> transmission_interface/SimpleTransmission </type>
    	<joint name="piston2_prismatic_joint">
      		<hardwareInterface> hardware_interface/PositionJointInterface </hardwareInterface>
    	</joint>
    	<actuator name= "piston2_motor">
      		<hardwareInterface> PositionJointInterface </hardwareInterface>
      		<mechanicalReduction> 1 </mechanicalReduction>
    	</actuator>
  	</transmission>

  	<transmission name="piston3_transmission">
    	<type> transmission_interface/SimpleTransmission </type>
    	<joint name="piston3_prismatic_joint">
      		<hardwareInterface> hardware_interface/PositionJointInterface </hardwareInterface>
    	</joint>
    	<actuator name= "piston3_motor">
      		<hardwareInterface> PositionJointInterface </hardwareInterface>
      		<mechanicalReduction> 1 </mechanicalReduction>
    	</actuator>
  	</transmission>

  	<transmission name="piston4_transmission">
    	<type> transmission_interface/SimpleTransmission </type>
    	<joint name="piston4_prismatic_joint">
      		<hardwareInterface> hardware_interface/PositionJointInterface </hardwareInterface>
    	</joint>
    	<actuator name= "piston4_motor">
      		<hardwareInterface> PositionJointInterface </hardwareInterface>
      		<mechanicalReduction> 1 </mechanicalReduction>
    	</actuator>
  	</transmission>

  	<transmission name="piston5_transmission">
    	<type> transmission_interface/SimpleTransmission </type>
    	<joint name="piston5_prismatic_joint">
      		<hardwareInterface> hardware_interface/PositionJointInterface </hardwareInterface>
    	</joint>
    	<actuator name= "piston5_motor">
      		<hardwareInterface> PositionJointInterface </hardwareInterface>
      		<mechanicalReduction> 1 </mechanicalReduction>
    	</actuator>
  	</transmission>

  	<transmission name="piston6_transmission">
    	<type> transmission_interface/SimpleTransmission </type>
    	<joint name="piston6_prismatic_joint">
      		<hardwareInterface> hardware_interface/PositionJointInterface </hardwareInterface>
    	</joint>
    	<actuator name= "piston6_motor">
      		<hardwareInterface> PositionJointInterface </hardwareInterface>
      		<mechanicalReduction> 1 </mechanicalReduction>
    	</actuator>
  	</transmission>

	<link name = "base_link" >
		<inertial>
			<mass value = "<%= BASE_MASS %>" />
			<origin xyz = "0 0 <%= BASE_HEIGHT/2 %>" rpy = "0 0 0" />
			<inertia ixx = "<%= BASE_MASS*((BASE_HEIGHT**2)/12.0+(BASE_RADIUS**2)/4) %>"
					 ixy = "0.0"
					 ixz = "0.0"
					 iyy = "<%= BASE_MASS*((BASE_HEIGHT**2)/12.0+(BASE_RADIUS**2)/4) %>"
					 iyz = "0.0"
					 izz = "<%= (BASE_MASS*BASE_RADIUS**2)/2 %>" />
		</inertial>

		<visual name = "base_link_visual" >
			<origin xyz = "0 0 <%= BASE_HEIGHT/2 %>" rpy = "0 0 0" />
			<geometry>
				<cylinder radius = "<%= BASE_RADIUS %>" length = "<%= BASE_HEIGHT %>" />
			</geometry>
		</visual>

		<collision name = "base_link_collision" >
			<origin xyz = "0 0 <%= BASE_HEIGHT/2 %>" rpy = "0 0 0" />
			<geometry>
				<cylinder radius = "<%= BASE_RADIUS %>" length = "<%= BASE_HEIGHT %>" />
			</geometry>
		</collision>
	</link>

	<link name = "bottom_ball1_link" >
		<inertial>
			<mass value = "0.1" />
			<origin xyz = "0 0 0" rpy = "0 0 0" />
			<inertia ixx = "0.0"
					 ixy = "0.0"
					 ixz = "0.0"
					 iyy = "0.0"
					 iyz = "0.0"
					 izz = "0.0" />
		</inertial>

		<visual name = "bottom_ball1_link_visual" >
			<origin xyz = "0 0 0" rpy = "0 0 0" />
			<geometry>
				<sphere radius = "<%= BALL_RADIUS %>" />
			</geometry>
		</visual>

		<collision name = "bottom_ball1_link_collision" >
			<origin xyz = "0 0 0" rpy = "0 0 0" />
			<geometry>
				<sphere radius = "<%= BALL_RADIUS %>" />
			</geometry>
		</collision>
	</link>

	<link name = "bottom_ball2_link" >
		<inertial>
			<mass value = "0.1" />
			<origin xyz = "0 0 0" rpy = "0 0 0" />
			<inertia ixx = "0.0"
					 ixy = "0.0"
					 ixz = "0.0"
					 iyy = "0.0"
					 iyz = "0.0"
					 izz = "0.0" />
		</inertial>

		<visual name = "bottom_ball2_link_visual" >
			<origin xyz = "0 0 0" rpy = "0 0 0" />
			<geometry>
				<sphere radius = "<%= BALL_RADIUS %>" />
			</geometry>
		</visual>

		<collision name = "bottom_ball2_link_collision" >
			<origin xyz = "0 0 0" rpy = "0 0 0" />
			<geometry>
				<sphere radius = "<%= BALL_RADIUS %>" />
			</geometry>
		</collision>
	</link>

	<link name = "bottom_ball3_link" >
		<inertial>
			<mass value = "0.1" />
			<origin xyz = "0 0 0" rpy = "0 0 0" />
			<inertia ixx = "0.0"
					 ixy = "0.0"
					 ixz = "0.0"
					 iyy = "0.0"
					 iyz = "0.0"
					 izz = "0.0" />
		</inertial>

		<visual name = "bottom_ball3_link_visual" >
			<origin xyz = "0 0 0" rpy = "0 0 0" />
			<geometry>
				<sphere radius = "<%= BALL_RADIUS %>" />
			</geometry>
		</visual>

		<collision name = "bottom_ball3_link_collision" >
			<origin xyz = "0 0 0" rpy = "0 0 0" />
			<geometry>
				<sphere radius = "<%= BALL_RADIUS %>" />
			</geometry>
		</collision>
	</link>

	<link name = "bottom_ball4_link" >
		<inertial>
			<mass value = "0.1" />
			<origin xyz = "0 0 0" rpy = "0 0 0" />
			<inertia ixx = "0.0"
					 ixy = "0.0"
					 ixz = "0.0"
					 iyy = "0.0"
					 iyz = "0.0"
					 izz = "0.0" />
		</inertial>

		<visual name = "bottom_ball4_link_visual" >
			<origin xyz = "0 0 0" rpy = "0 0 0" />
			<geometry>
				<sphere radius = "<%= BALL_RADIUS %>" />
			</geometry>
		</visual>

		<collision name = "bottom_ball4_link_collision" >
			<origin xyz = "0 0 0" rpy = "0 0 0" />
			<geometry>
				<sphere radius = "<%= BALL_RADIUS %>" />
			</geometry>
		</collision>
	</link>

	<link name = "bottom_ball5_link" >
		<inertial>
			<mass value = "0.1" />
			<origin xyz = "0 0 0" rpy = "0 0 0" />
			<inertia ixx = "0.0"
					 ixy = "0.0"
					 ixz = "0.0"
					 iyy = "0.0"
					 iyz = "0.0"
					 izz = "0.0" />
		</inertial>

		<visual name = "bottom_ball5_link_visual" >
			<origin xyz = "0 0 0" rpy = "0 0 0" />
			<geometry>
				<sphere radius = "<%= BALL_RADIUS %>" />
			</geometry>
		</visual>

		<collision name = "bottom_ball5_link_collision" >
			<origin xyz = "0 0 0" rpy = "0 0 0" />
			<geometry>
				<sphere radius = "<%= BALL_RADIUS %>" />
			</geometry>
		</collision>
	</link>

	<link name = "bottom_ball6_link" >
		<inertial>
			<mass value = "0.1" />
			<origin xyz = "0 0 0" rpy = "0 0 0" />
			<inertia ixx = "0.0"
					 ixy = "0.0"
					 ixz = "0.0"
					 iyy = "0.0"
					 iyz = "0.0"
					 izz = "0.0" />
		</inertial>

		<visual name = "bottom_ball6_link_visual" >
			<origin xyz = "0 0 0" rpy = "0 0 0" />
			<geometry>
				<sphere radius = "<%= BALL_RADIUS %>" />
			</geometry>
		</visual>

		<collision name = "bottom_ball6_link_collision" >
			<origin xyz = "0 0 0" rpy = "0 0 0" />
			<geometry>
				<sphere radius = "<%= BALL_RADIUS %>" />
			</geometry>
		</collision>
	</link>

	<link name = "piston1_cylinder_link" >
		<inertial>
			<mass value = "0.1" />
			<origin xyz = "0 0 <%= 0.5*PISTON_LENGTH %>" rpy = "0 0 0" />
			<inertia ixx = "0.0"
					 ixy = "0.0"
					 ixz = "0.0"
					 iyy = "0.0"
					 iyz = "0.0"
					 izz = "0.0" />
		</inertial>

		<visual name = "piston1_cylinder_link_visual" >
			<origin xyz = "0 0 <%= 0.5*PISTON_LENGTH %>" rpy = "0 0 0" />
			<geometry>
				<cylinder radius = "<%= PISTON_RADIUS %>" length = "<%= PISTON_LENGTH %>" />
			</geometry>
		</visual>

		<collision name = "piston1_link_collision" >
			<origin xyz = "0 0 <%= 0.5*PISTON_LENGTH %>" rpy = "0 0 0" />
			<geometry>
				<cylinder radius = "<%= PISTON_RADIUS %>" length = "<%= PISTON_LENGTH %>" />
			</geometry>
		</collision>
	</link>

	<link name = "piston2_cylinder_link" >
		<inertial>
			<mass value = "0.1" />
			<origin xyz = "0 0 <%= 0.5*PISTON_LENGTH %>" rpy = "0 0 0" />
			<inertia ixx = "0.0"
					 ixy = "0.0"
					 ixz = "0.0"
					 iyy = "0.0"
					 iyz = "0.0"
					 izz = "0.0" />
		</inertial>

		<visual name = "piston2_cylinder_link_visual" >
			<origin xyz = "0 0 <%= 0.5*PISTON_LENGTH %>" rpy = "0 0 0" />
			<geometry>
				<cylinder radius = "<%= PISTON_RADIUS %>" length = "<%= PISTON_LENGTH %>" />
			</geometry>
		</visual>

		<collision name = "piston2_link_collision" >
			<origin xyz = "0 0 <%= 0.5*PISTON_LENGTH %>" rpy = "0 0 0" />
			<geometry>
				<cylinder radius = "<%= PISTON_RADIUS %>" length = "<%= PISTON_LENGTH %>" />
			</geometry>
		</collision>
	</link>

	<link name = "piston3_cylinder_link" >
		<inertial>
			<mass value = "0.1" />
			<origin xyz = "0 0 <%= 0.5*PISTON_LENGTH %>" rpy = "0 0 0" />
			<inertia ixx = "0.0"
					 ixy = "0.0"
					 ixz = "0.0"
					 iyy = "0.0"
					 iyz = "0.0"
					 izz = "0.0" />
		</inertial>

		<visual name = "piston3_cylinder_link_visual" >
			<origin xyz = "0 0 <%= 0.5*PISTON_LENGTH %>" rpy = "0 0 0" />
			<geometry>
				<cylinder radius = "<%= PISTON_RADIUS %>" length = "<%= PISTON_LENGTH %>" />
			</geometry>
		</visual>

		<collision name = "piston3_link_collision" >
			<origin xyz = "0 0 <%= 0.5*PISTON_LENGTH %>" rpy = "0 0 0" />
			<geometry>
				<cylinder radius = "<%= PISTON_RADIUS %>" length = "<%= PISTON_LENGTH %>" />
			</geometry>
		</collision>
	</link>

	<link name = "piston4_cylinder_link" >
		<inertial>
			<mass value = "0.1" />
			<origin xyz = "0 0 <%= 0.5*PISTON_LENGTH %>" rpy = "0 0 0" />
			<inertia ixx = "0.0"
					 ixy = "0.0"
					 ixz = "0.0"
					 iyy = "0.0"
					 iyz = "0.0"
					 izz = "0.0" />
		</inertial>

		<visual name = "piston4_cylinder_link_visual" >
			<origin xyz = "0 0 <%= 0.5*PISTON_LENGTH %>" rpy = "0 0 0" />
			<geometry>
				<cylinder radius = "<%= PISTON_RADIUS %>" length = "<%= PISTON_LENGTH %>" />
			</geometry>
		</visual>

		<collision name = "piston4_link_collision" >
			<origin xyz = "0 0 <%= 0.5*PISTON_LENGTH %>" rpy = "0 0 0" />
			<geometry>
				<cylinder radius = "<%= PISTON_RADIUS %>" length = "<%= PISTON_LENGTH %>" />
			</geometry>
		</collision>
	</link>

	<link name = "piston5_cylinder_link" >
		<inertial>
			<mass value = "0.1" />
			<origin xyz = "0 0 <%= 0.5*PISTON_LENGTH %>" rpy = "0 0 0" />
			<inertia ixx = "0.0"
					 ixy = "0.0"
					 ixz = "0.0"
					 iyy = "0.0"
					 iyz = "0.0"
					 izz = "0.0" />
		</inertial>

		<visual name = "piston5_cylinder_link_visual" >
			<origin xyz = "0 0 <%= 0.5*PISTON_LENGTH %>" rpy = "0 0 0" />
			<geometry>
				<cylinder radius = "<%= PISTON_RADIUS %>" length = "<%= PISTON_LENGTH %>" />
			</geometry>
		</visual>

		<collision name = "piston5_link_collision" >
			<origin xyz = "0 0 <%= 0.5*PISTON_LENGTH %>" rpy = "0 0 0" />
			<geometry>
				<cylinder radius = "<%= PISTON_RADIUS %>" length = "<%= PISTON_LENGTH %>" />
			</geometry>
		</collision>
	</link>

	<link name = "piston6_cylinder_link" >
		<inertial>
			<mass value = "0.1" />
			<origin xyz = "0 0 <%= 0.5*PISTON_LENGTH %>" rpy = "0 0 0" />
			<inertia ixx = "0.0"
					 ixy = "0.0"
					 ixz = "0.0"
					 iyy = "0.0"
					 iyz = "0.0"
					 izz = "0.0" />
		</inertial>

		<visual name = "piston6_cylinder_link_visual" >
			<origin xyz = "0 0 <%= 0.5*PISTON_LENGTH %>" rpy = "0 0 0" />
			<geometry>
				<cylinder radius = "<%= PISTON_RADIUS %>" length = "<%= PISTON_LENGTH %>" />
			</geometry>
		</visual>

		<collision name = "piston6_link_collision" >
			<origin xyz = "0 0 <%= 0.5*PISTON_LENGTH %>" rpy = "0 0 0" />
			<geometry>
				<cylinder radius = "<%= PISTON_RADIUS %>" length = "<%= PISTON_LENGTH %>" />
			</geometry>
		</collision>
	</link>

	<link name = "piston1_shaft_link" >
		<inertial>
			<mass value = "0.1" />
			<origin xyz = "0 0 0" rpy = "0 0 0" />
			<inertia ixx = "0.0"
					 ixy = "0.0"
					 ixz = "0.0"
					 iyy = "0.0"
					 iyz = "0.0"
					 izz = "0.0" />
		</inertial>

		<visual name = "piston1_shaft_visual" >
			<origin xyz = "0 0 0" rpy = "0 0 0" />
			<geometry>
				<cylinder radius = "<%= 0.5*PISTON_RADIUS %>" length = "<%= 0.5*PISTON_LENGTH %>" />
			</geometry>
		</visual>

		<collision name = "piston1_shaft_collision" >
			<origin xyz = "0 0 0" rpy = "0 0 0" />
			<geometry>
				<cylinder radius = "<%= 0.5*PISTON_RADIUS %>" length = "<%= 0.5*PISTON_LENGTH %>" />
			</geometry>
		</collision>
	</link>

	<link name = "piston2_shaft_link" >
		<inertial>
			<mass value = "0.1" />
			<origin xyz = "0 0 0" rpy = "0 0 0" />
			<inertia ixx = "0.0"
					 ixy = "0.0"
					 ixz = "0.0"
					 iyy = "0.0"
					 iyz = "0.0"
					 izz = "0.0" />
		</inertial>

		<visual name = "piston2_shaft_visual" >
			<origin xyz = "0 0 0" rpy = "0 0 0" />
			<geometry>
				<cylinder radius = "<%= 0.5*PISTON_RADIUS %>" length = "<%= 0.5*PISTON_LENGTH %>" />
			</geometry>
		</visual>

		<collision name = "piston2_shaft_collision" >
			<origin xyz = "0 0 0" rpy = "0 0 0" />
			<geometry>
				<cylinder radius = "<%= 0.5*PISTON_RADIUS %>" length = "<%= 0.5*PISTON_LENGTH %>" />
			</geometry>
		</collision>
	</link>

	<link name = "piston3_shaft_link" >
		<inertial>
			<mass value = "0.1" />
			<origin xyz = "0 0 0" rpy = "0 0 0" />
			<inertia ixx = "0.0"
					 ixy = "0.0"
					 ixz = "0.0"
					 iyy = "0.0"
					 iyz = "0.0"
					 izz = "0.0" />
		</inertial>

		<visual name = "piston3_shaft_visual" >
			<origin xyz = "0 0 0" rpy = "0 0 0" />
			<geometry>
				<cylinder radius = "<%= 0.5*PISTON_RADIUS %>" length = "<%= 0.5*PISTON_LENGTH %>" />
			</geometry>
		</visual>

		<collision name = "piston3_shaft_collision" >
			<origin xyz = "0 0 0" rpy = "0 0 0" />
			<geometry>
				<cylinder radius = "<%= 0.5*PISTON_RADIUS %>" length = "<%= 0.5*PISTON_LENGTH %>" />
			</geometry>
		</collision>
	</link>

	<link name = "piston4_shaft_link" >
		<inertial>
			<mass value = "0.1" />
			<origin xyz = "0 0 0" rpy = "0 0 0" />
			<inertia ixx = "0.0"
					 ixy = "0.0"
					 ixz = "0.0"
					 iyy = "0.0"
					 iyz = "0.0"
					 izz = "0.0" />
		</inertial>

		<visual name = "piston4_shaft_visual" >
			<origin xyz = "0 0 0" rpy = "0 0 0" />
			<geometry>
				<cylinder radius = "<%= 0.5*PISTON_RADIUS %>" length = "<%= 0.5*PISTON_LENGTH %>" />
			</geometry>
		</visual>

		<collision name = "piston4_shaft_collision" >
			<origin xyz = "0 0 0" rpy = "0 0 0" />
			<geometry>
				<cylinder radius = "<%= 0.5*PISTON_RADIUS %>" length = "<%= 0.5*PISTON_LENGTH %>" />
			</geometry>
		</collision>
	</link>

	<link name = "piston5_shaft_link" >
		<inertial>
			<mass value = "0.1" />
			<origin xyz = "0 0 0" rpy = "0 0 0" />
			<inertia ixx = "0.0"
					 ixy = "0.0"
					 ixz = "0.0"
					 iyy = "0.0"
					 iyz = "0.0"
					 izz = "0.0" />
		</inertial>

		<visual name = "piston5_shaft_visual" >
			<origin xyz = "0 0 0" rpy = "0 0 0" />
			<geometry>
				<cylinder radius = "<%= 0.5*PISTON_RADIUS %>" length = "<%= 0.5*PISTON_LENGTH %>" />
			</geometry>
		</visual>

		<collision name = "piston5_shaft_collision" >
			<origin xyz = "0 0 0" rpy = "0 0 0" />
			<geometry>
				<cylinder radius = "<%= 0.5*PISTON_RADIUS %>" length = "<%= 0.5*PISTON_LENGTH %>" />
			</geometry>
		</collision>
	</link>

	<link name = "piston6_shaft_link" >
		<inertial>
			<mass value = "0.1" />
			<origin xyz = "0 0 0" rpy = "0 0 0" />
			<inertia ixx = "0.0"
					 ixy = "0.0"
					 ixz = "0.0"
					 iyy = "0.0"
					 iyz = "0.0"
					 izz = "0.0" />
		</inertial>

		<visual name = "piston6_shaft_visual" >
			<origin xyz = "0 0 0" rpy = "0 0 0" />
			<geometry>
				<cylinder radius = "<%= 0.5*PISTON_RADIUS %>" length = "<%= 0.5*PISTON_LENGTH %>" />
			</geometry>
		</visual>

		<collision name = "piston6_shaft_collision" >
			<origin xyz = "0 0 0" rpy = "0 0 0" />
			<geometry>
				<cylinder radius = "<%= 0.5*PISTON_RADIUS %>" length = "<%= 0.5*PISTON_LENGTH %>" />
			</geometry>
		</collision>
	</link>

	<gazebo>
	  <static> false </static>

	  <plugin name="gazebo_ros_control" filename="libgazebo_ros_control.so">
	    <robotNamespace> /stewart </robotNamespace>
	  </plugin>
	</gazebo>
</robot>