<? xml version = "1.0" ?>

<robot name= "stewart" >
	<joint name = "bottom_ball1_joint" type = "continuous" >
		<parent link = "base_link" />
		<child link = "bottom_ball1_link" />
		<origin xyz = "-0.10094113843523252 0.7998817953744161 0.25" rpy = "0 0 0" />
		<axis xyz = "0 0 1" />
	</joint>

	<joint name = "bottom_ball2_joint" type = "continuous" >
		<parent link = "base_link" />
		<child link = "bottom_ball2_link" />
		<origin xyz = "0.10061530109167109 0.7999228470210314 0.25" rpy = "0 0 0" />
		<axis xyz = "0 0 1" />
	</joint>

	<joint name = "bottom_ball3_joint" type = "continuous" >
		<parent link = "base_link" />
		<child link = "bottom_ball3_link" />
		<origin xyz = "0.7429993434805581 -0.3129728032712424 0.25" rpy = "0 0 0" />
		<axis xyz = "0 0 1" />
	</joint>

	<joint name = "bottom_ball4_joint" type = "continuous" >
		<parent link = "base_link" />
		<child link = "bottom_ball4_link" />
		<origin xyz = "0.6421510948171859 -0.4874853550878114 0.25" rpy = "0 0 0" />
		<axis xyz = "0 0 1" />
	</joint>

	<joint name = "bottom_ball5_joint" type = "continuous" >
		<parent link = "base_link" />
		<child link = "bottom_ball5_link" />
		<origin xyz = "-0.6433227790696778 -0.48593806388269956 0.25" rpy = "0 0 0" />
		<axis xyz = "0 0 1" />
	</joint>

	<joint name = "bottom_ball6_joint" type = "continuous" >
		<parent link = "base_link" />
		<child link = "bottom_ball6_link" />
		<origin xyz = "-0.743750623750048 -0.31118324130874175 0.25" rpy = "0 0 0" />
		<axis xyz = "0 0 1" />
	</joint>

	<joint name = "piston1_pitch_joint" type = "continuous" >
		<parent link = "bottom_ball1_link" />
		<child link = "piston1_cylinder_link" />
		<origin xyz = "0 0 0" rpy = "-0.25183674477965967 0 2.0945" />
		<axis xyz = "1 0 0" />
	</joint>

	<joint name = "piston2_pitch_joint" type = "continuous" >
		<parent link = "bottom_ball2_link" />
		<child link = "piston2_cylinder_link" />
		<origin xyz = "0 0 0" rpy = "0.25183674477965967 0 1.0474999999999999" />
		<axis xyz = "1 0 0" />
	</joint>

	<joint name = "piston3_pitch_joint" type = "continuous" >
		<parent link = "bottom_ball3_link" />
		<child link = "piston3_cylinder_link" />
		<origin xyz = "0 0 0" rpy = "-0.25183674477965967 0 0.17450000000000004" />
		<axis xyz = "1 0 0" />
	</joint>

	<joint name = "piston4_pitch_joint" type = "continuous" >
		<parent link = "bottom_ball4_link" />
		<child link = "piston4_cylinder_link" />
		<origin xyz = "0 0 0" rpy = "0.25183674477965967 0 -0.8725" />
		<axis xyz = "1 0 0" />
	</joint>

	<joint name = "piston5_pitch_joint" type = "continuous" >
		<parent link = "bottom_ball5_link" />
		<child link = "piston5_cylinder_link" />
		<origin xyz = "0 0 0" rpy = "-0.25183674477965967 0 -2.0965" />
		<axis xyz = "1 0 0" />
	</joint>

	<joint name = "piston6_pitch_joint" type = "continuous" >
		<parent link = "bottom_ball6_link" />
		<child link = "piston6_cylinder_link" />
		<origin xyz = "0 0 0" rpy = "0.25183674477965967 0 -3.1435000000000004" />
		<axis xyz = "1 0 0" />
	</joint>

	<joint name = "piston1_prismatic_joint" type = "prismatic" >
		<parent link = "piston1_cylinder_link" />
		<child link = "piston1_shaft_link" />
		<origin xyz = "0 0 1.548775427316394" rpy = "0 0 0" />
		<axis xyz = "0 0 1" />
		<limit effort= "10" velocity= "1" lower = "0" upper = "1.0325169515442627" />
	</joint>

	<joint name = "piston2_prismatic_joint" type = "prismatic" >
		<parent link = "piston2_cylinder_link" />
		<child link = "piston2_shaft_link" />
		<origin xyz = "0 0 1.548775427316394" rpy = "0 0 0" />
		<axis xyz = "0 0 1" />
		<limit effort= "10" velocity= "10" lower = "0" upper = "1.0325169515442627" />
	</joint>

	<joint name = "piston3_prismatic_joint" type = "prismatic" >
		<parent link = "piston3_cylinder_link" />
		<child link = "piston3_shaft_link" />
		<origin xyz = "0 0 1.548775427316394" rpy = "0 0 0" />
		<axis xyz = "0 0 1" />
		<limit effort= "10" velocity= "10" lower = "0" upper = "1.0325169515442627" />
	</joint>

	<joint name = "piston4_prismatic_joint" type = "prismatic" >
		<parent link = "piston4_cylinder_link" />
		<child link = "piston4_shaft_link" />
		<origin xyz = "0 0 1.548775427316394" rpy = "0 0 0" />
		<axis xyz = "0 0 1" />
		<limit effort= "10" velocity= "10" lower = "0" upper = "1.0325169515442627" />
	</joint>

	<joint name = "piston5_prismatic_joint" type = "prismatic" >
		<parent link = "piston5_cylinder_link" />
		<child link = "piston5_shaft_link" />
		<origin xyz = "0 0 1.548775427316394" rpy = "0 0 0" />
		<axis xyz = "0 0 1" />
		<limit effort= "10" velocity= "10" lower = "0" upper = "1.0325169515442627" />
	</joint>

	<joint name = "piston6_prismatic_joint" type = "prismatic" >
		<parent link = "piston6_cylinder_link" />
		<child link = "piston6_shaft_link" />
		<origin xyz = "0 0 1.548775427316394" rpy = "0 0 0" />
		<axis xyz = "0 0 1" />
		<limit effort= "10" velocity= "10" lower = "0" upper = "1.0325169515442627" />
	</joint>

  	<transmission name="piston1_transmission">
    	<type> transmission_interface/SimpleTransmission </type>
    	<joint name="piston1_prismatic_joint">
      		<hardwareInterface> hardware_interface/PositionJointInterface </hardwareInterface>
    	</joint>
    	<actuator name= "piston1_motor">
      		<hardwareInterface> PositionJointInterface </hardwareInterface>
      		<mechanicalReduction> 1 </mechanicalReduction>
    	</actuator>
  	</transmission>

  	<transmission name="piston2_transmission">
    	<type> transmission_interface/SimpleTransmission </type>
    	<joint name="piston2_prismatic_joint">
      		<hardwareInterface> hardware_interface/PositionJointInterface </hardwareInterface>
    	</joint>
    	<actuator name= "piston2_motor">
      		<hardwareInterface> PositionJointInterface </hardwareInterface>
      		<mechanicalReduction> 1 </mechanicalReduction>
    	</actuator>
  	</transmission>

  	<transmission name="piston3_transmission">
    	<type> transmission_interface/SimpleTransmission </type>
    	<joint name="piston3_prismatic_joint">
      		<hardwareInterface> hardware_interface/PositionJointInterface </hardwareInterface>
    	</joint>
    	<actuator name= "piston3_motor">
      		<hardwareInterface> PositionJointInterface </hardwareInterface>
      		<mechanicalReduction> 1 </mechanicalReduction>
    	</actuator>
  	</transmission>

  	<transmission name="piston4_transmission">
    	<type> transmission_interface/SimpleTransmission </type>
    	<joint name="piston4_prismatic_joint">
      		<hardwareInterface> hardware_interface/PositionJointInterface </hardwareInterface>
    	</joint>
    	<actuator name= "piston4_motor">
      		<hardwareInterface> PositionJointInterface </hardwareInterface>
      		<mechanicalReduction> 1 </mechanicalReduction>
    	</actuator>
  	</transmission>

  	<transmission name="piston5_transmission">
    	<type> transmission_interface/SimpleTransmission </type>
    	<joint name="piston5_prismatic_joint">
      		<hardwareInterface> hardware_interface/PositionJointInterface </hardwareInterface>
    	</joint>
    	<actuator name= "piston5_motor">
      		<hardwareInterface> PositionJointInterface </hardwareInterface>
      		<mechanicalReduction> 1 </mechanicalReduction>
    	</actuator>
  	</transmission>

  	<transmission name="piston6_transmission">
    	<type> transmission_interface/SimpleTransmission </type>
    	<joint name="piston6_prismatic_joint">
      		<hardwareInterface> hardware_interface/PositionJointInterface </hardwareInterface>
    	</joint>
    	<actuator name= "piston6_motor">
      		<hardwareInterface> PositionJointInterface </hardwareInterface>
      		<mechanicalReduction> 1 </mechanicalReduction>
    	</actuator>
  	</transmission>

	<link name = "base_link" >
		<inertial>
			<mass value = "10.0" />
			<origin xyz = "0 0 0.125" rpy = "0 0 0" />
			<inertia ixx = "2.552083333333333"
					 ixy = "0.0"
					 ixz = "0.0"
					 iyy = "2.552083333333333"
					 iyz = "0.0"
					 izz = "5.0" />
		</inertial>

		<visual name = "base_link_visual" >
			<origin xyz = "0 0 0.125" rpy = "0 0 0" />
			<geometry>
				<cylinder radius = "1.0" length = "0.25" />
			</geometry>
		</visual>

		<collision name = "base_link_collision" >
			<origin xyz = "0 0 0.125" rpy = "0 0 0" />
			<geometry>
				<cylinder radius = "1.0" length = "0.25" />
			</geometry>
		</collision>
	</link>

	<link name = "bottom_ball1_link" >
		<inertial>
			<mass value = "0.1" />
			<origin xyz = "0 0 0" rpy = "0 0 0" />
			<inertia ixx = "0.0"
					 ixy = "0.0"
					 ixz = "0.0"
					 iyy = "0.0"
					 iyz = "0.0"
					 izz = "0.0" />
		</inertial>

		<visual name = "bottom_ball1_link_visual" >
			<origin xyz = "0 0 0" rpy = "0 0 0" />
			<geometry>
				<sphere radius = "0.1" />
			</geometry>
		</visual>

		<collision name = "bottom_ball1_link_collision" >
			<origin xyz = "0 0 0" rpy = "0 0 0" />
			<geometry>
				<sphere radius = "0.1" />
			</geometry>
		</collision>
	</link>

	<link name = "bottom_ball2_link" >
		<inertial>
			<mass value = "0.1" />
			<origin xyz = "0 0 0" rpy = "0 0 0" />
			<inertia ixx = "0.0"
					 ixy = "0.0"
					 ixz = "0.0"
					 iyy = "0.0"
					 iyz = "0.0"
					 izz = "0.0" />
		</inertial>

		<visual name = "bottom_ball2_link_visual" >
			<origin xyz = "0 0 0" rpy = "0 0 0" />
			<geometry>
				<sphere radius = "0.1" />
			</geometry>
		</visual>

		<collision name = "bottom_ball2_link_collision" >
			<origin xyz = "0 0 0" rpy = "0 0 0" />
			<geometry>
				<sphere radius = "0.1" />
			</geometry>
		</collision>
	</link>

	<link name = "bottom_ball3_link" >
		<inertial>
			<mass value = "0.1" />
			<origin xyz = "0 0 0" rpy = "0 0 0" />
			<inertia ixx = "0.0"
					 ixy = "0.0"
					 ixz = "0.0"
					 iyy = "0.0"
					 iyz = "0.0"
					 izz = "0.0" />
		</inertial>

		<visual name = "bottom_ball3_link_visual" >
			<origin xyz = "0 0 0" rpy = "0 0 0" />
			<geometry>
				<sphere radius = "0.1" />
			</geometry>
		</visual>

		<collision name = "bottom_ball3_link_collision" >
			<origin xyz = "0 0 0" rpy = "0 0 0" />
			<geometry>
				<sphere radius = "0.1" />
			</geometry>
		</collision>
	</link>

	<link name = "bottom_ball4_link" >
		<inertial>
			<mass value = "0.1" />
			<origin xyz = "0 0 0" rpy = "0 0 0" />
			<inertia ixx = "0.0"
					 ixy = "0.0"
					 ixz = "0.0"
					 iyy = "0.0"
					 iyz = "0.0"
					 izz = "0.0" />
		</inertial>

		<visual name = "bottom_ball4_link_visual" >
			<origin xyz = "0 0 0" rpy = "0 0 0" />
			<geometry>
				<sphere radius = "0.1" />
			</geometry>
		</visual>

		<collision name = "bottom_ball4_link_collision" >
			<origin xyz = "0 0 0" rpy = "0 0 0" />
			<geometry>
				<sphere radius = "0.1" />
			</geometry>
		</collision>
	</link>

	<link name = "bottom_ball5_link" >
		<inertial>
			<mass value = "0.1" />
			<origin xyz = "0 0 0" rpy = "0 0 0" />
			<inertia ixx = "0.0"
					 ixy = "0.0"
					 ixz = "0.0"
					 iyy = "0.0"
					 iyz = "0.0"
					 izz = "0.0" />
		</inertial>

		<visual name = "bottom_ball5_link_visual" >
			<origin xyz = "0 0 0" rpy = "0 0 0" />
			<geometry>
				<sphere radius = "0.1" />
			</geometry>
		</visual>

		<collision name = "bottom_ball5_link_collision" >
			<origin xyz = "0 0 0" rpy = "0 0 0" />
			<geometry>
				<sphere radius = "0.1" />
			</geometry>
		</collision>
	</link>

	<link name = "bottom_ball6_link" >
		<inertial>
			<mass value = "0.1" />
			<origin xyz = "0 0 0" rpy = "0 0 0" />
			<inertia ixx = "0.0"
					 ixy = "0.0"
					 ixz = "0.0"
					 iyy = "0.0"
					 iyz = "0.0"
					 izz = "0.0" />
		</inertial>

		<visual name = "bottom_ball6_link_visual" >
			<origin xyz = "0 0 0" rpy = "0 0 0" />
			<geometry>
				<sphere radius = "0.1" />
			</geometry>
		</visual>

		<collision name = "bottom_ball6_link_collision" >
			<origin xyz = "0 0 0" rpy = "0 0 0" />
			<geometry>
				<sphere radius = "0.1" />
			</geometry>
		</collision>
	</link>

	<link name = "piston1_cylinder_link" >
		<inertial>
			<mass value = "0.1" />
			<origin xyz = "0 0 1.0325169515442627" rpy = "0 0 0" />
			<inertia ixx = "0.0"
					 ixy = "0.0"
					 ixz = "0.0"
					 iyy = "0.0"
					 iyz = "0.0"
					 izz = "0.0" />
		</inertial>

		<visual name = "piston1_cylinder_link_visual" >
			<origin xyz = "0 0 1.0325169515442627" rpy = "0 0 0" />
			<geometry>
				<cylinder radius = "0.1" length = "2.0650339030885254" />
			</geometry>
		</visual>

		<collision name = "piston1_link_collision" >
			<origin xyz = "0 0 1.0325169515442627" rpy = "0 0 0" />
			<geometry>
				<cylinder radius = "0.1" length = "2.0650339030885254" />
			</geometry>
		</collision>
	</link>

	<link name = "piston2_cylinder_link" >
		<inertial>
			<mass value = "0.1" />
			<origin xyz = "0 0 1.0325169515442627" rpy = "0 0 0" />
			<inertia ixx = "0.0"
					 ixy = "0.0"
					 ixz = "0.0"
					 iyy = "0.0"
					 iyz = "0.0"
					 izz = "0.0" />
		</inertial>

		<visual name = "piston2_cylinder_link_visual" >
			<origin xyz = "0 0 1.0325169515442627" rpy = "0 0 0" />
			<geometry>
				<cylinder radius = "0.1" length = "2.0650339030885254" />
			</geometry>
		</visual>

		<collision name = "piston2_link_collision" >
			<origin xyz = "0 0 1.0325169515442627" rpy = "0 0 0" />
			<geometry>
				<cylinder radius = "0.1" length = "2.0650339030885254" />
			</geometry>
		</collision>
	</link>

	<link name = "piston3_cylinder_link" >
		<inertial>
			<mass value = "0.1" />
			<origin xyz = "0 0 1.0325169515442627" rpy = "0 0 0" />
			<inertia ixx = "0.0"
					 ixy = "0.0"
					 ixz = "0.0"
					 iyy = "0.0"
					 iyz = "0.0"
					 izz = "0.0" />
		</inertial>

		<visual name = "piston3_cylinder_link_visual" >
			<origin xyz = "0 0 1.0325169515442627" rpy = "0 0 0" />
			<geometry>
				<cylinder radius = "0.1" length = "2.0650339030885254" />
			</geometry>
		</visual>

		<collision name = "piston3_link_collision" >
			<origin xyz = "0 0 1.0325169515442627" rpy = "0 0 0" />
			<geometry>
				<cylinder radius = "0.1" length = "2.0650339030885254" />
			</geometry>
		</collision>
	</link>

	<link name = "piston4_cylinder_link" >
		<inertial>
			<mass value = "0.1" />
			<origin xyz = "0 0 1.0325169515442627" rpy = "0 0 0" />
			<inertia ixx = "0.0"
					 ixy = "0.0"
					 ixz = "0.0"
					 iyy = "0.0"
					 iyz = "0.0"
					 izz = "0.0" />
		</inertial>

		<visual name = "piston4_cylinder_link_visual" >
			<origin xyz = "0 0 1.0325169515442627" rpy = "0 0 0" />
			<geometry>
				<cylinder radius = "0.1" length = "2.0650339030885254" />
			</geometry>
		</visual>

		<collision name = "piston4_link_collision" >
			<origin xyz = "0 0 1.0325169515442627" rpy = "0 0 0" />
			<geometry>
				<cylinder radius = "0.1" length = "2.0650339030885254" />
			</geometry>
		</collision>
	</link>

	<link name = "piston5_cylinder_link" >
		<inertial>
			<mass value = "0.1" />
			<origin xyz = "0 0 1.0325169515442627" rpy = "0 0 0" />
			<inertia ixx = "0.0"
					 ixy = "0.0"
					 ixz = "0.0"
					 iyy = "0.0"
					 iyz = "0.0"
					 izz = "0.0" />
		</inertial>

		<visual name = "piston5_cylinder_link_visual" >
			<origin xyz = "0 0 1.0325169515442627" rpy = "0 0 0" />
			<geometry>
				<cylinder radius = "0.1" length = "2.0650339030885254" />
			</geometry>
		</visual>

		<collision name = "piston5_link_collision" >
			<origin xyz = "0 0 1.0325169515442627" rpy = "0 0 0" />
			<geometry>
				<cylinder radius = "0.1" length = "2.0650339030885254" />
			</geometry>
		</collision>
	</link>

	<link name = "piston6_cylinder_link" >
		<inertial>
			<mass value = "0.1" />
			<origin xyz = "0 0 1.0325169515442627" rpy = "0 0 0" />
			<inertia ixx = "0.0"
					 ixy = "0.0"
					 ixz = "0.0"
					 iyy = "0.0"
					 iyz = "0.0"
					 izz = "0.0" />
		</inertial>

		<visual name = "piston6_cylinder_link_visual" >
			<origin xyz = "0 0 1.0325169515442627" rpy = "0 0 0" />
			<geometry>
				<cylinder radius = "0.1" length = "2.0650339030885254" />
			</geometry>
		</visual>

		<collision name = "piston6_link_collision" >
			<origin xyz = "0 0 1.0325169515442627" rpy = "0 0 0" />
			<geometry>
				<cylinder radius = "0.1" length = "2.0650339030885254" />
			</geometry>
		</collision>
	</link>

	<link name = "piston1_shaft_link" >
		<inertial>
			<mass value = "0.1" />
			<origin xyz = "0 0 0" rpy = "0 0 0" />
			<inertia ixx = "0.0"
					 ixy = "0.0"
					 ixz = "0.0"
					 iyy = "0.0"
					 iyz = "0.0"
					 izz = "0.0" />
		</inertial>

		<visual name = "piston1_shaft_visual" >
			<origin xyz = "0 0 0" rpy = "0 0 0" />
			<geometry>
				<cylinder radius = "0.05" length = "1.0325169515442627" />
			</geometry>
		</visual>

		<collision name = "piston1_shaft_collision" >
			<origin xyz = "0 0 0" rpy = "0 0 0" />
			<geometry>
				<cylinder radius = "0.05" length = "1.0325169515442627" />
			</geometry>
		</collision>
	</link>

	<link name = "piston2_shaft_link" >
		<inertial>
			<mass value = "0.1" />
			<origin xyz = "0 0 0" rpy = "0 0 0" />
			<inertia ixx = "0.0"
					 ixy = "0.0"
					 ixz = "0.0"
					 iyy = "0.0"
					 iyz = "0.0"
					 izz = "0.0" />
		</inertial>

		<visual name = "piston2_shaft_visual" >
			<origin xyz = "0 0 0" rpy = "0 0 0" />
			<geometry>
				<cylinder radius = "0.05" length = "1.0325169515442627" />
			</geometry>
		</visual>

		<collision name = "piston2_shaft_collision" >
			<origin xyz = "0 0 0" rpy = "0 0 0" />
			<geometry>
				<cylinder radius = "0.05" length = "1.0325169515442627" />
			</geometry>
		</collision>
	</link>

	<link name = "piston3_shaft_link" >
		<inertial>
			<mass value = "0.1" />
			<origin xyz = "0 0 0" rpy = "0 0 0" />
			<inertia ixx = "0.0"
					 ixy = "0.0"
					 ixz = "0.0"
					 iyy = "0.0"
					 iyz = "0.0"
					 izz = "0.0" />
		</inertial>

		<visual name = "piston3_shaft_visual" >
			<origin xyz = "0 0 0" rpy = "0 0 0" />
			<geometry>
				<cylinder radius = "0.05" length = "1.0325169515442627" />
			</geometry>
		</visual>

		<collision name = "piston3_shaft_collision" >
			<origin xyz = "0 0 0" rpy = "0 0 0" />
			<geometry>
				<cylinder radius = "0.05" length = "1.0325169515442627" />
			</geometry>
		</collision>
	</link>

	<link name = "piston4_shaft_link" >
		<inertial>
			<mass value = "0.1" />
			<origin xyz = "0 0 0" rpy = "0 0 0" />
			<inertia ixx = "0.0"
					 ixy = "0.0"
					 ixz = "0.0"
					 iyy = "0.0"
					 iyz = "0.0"
					 izz = "0.0" />
		</inertial>

		<visual name = "piston4_shaft_visual" >
			<origin xyz = "0 0 0" rpy = "0 0 0" />
			<geometry>
				<cylinder radius = "0.05" length = "1.0325169515442627" />
			</geometry>
		</visual>

		<collision name = "piston4_shaft_collision" >
			<origin xyz = "0 0 0" rpy = "0 0 0" />
			<geometry>
				<cylinder radius = "0.05" length = "1.0325169515442627" />
			</geometry>
		</collision>
	</link>

	<link name = "piston5_shaft_link" >
		<inertial>
			<mass value = "0.1" />
			<origin xyz = "0 0 0" rpy = "0 0 0" />
			<inertia ixx = "0.0"
					 ixy = "0.0"
					 ixz = "0.0"
					 iyy = "0.0"
					 iyz = "0.0"
					 izz = "0.0" />
		</inertial>

		<visual name = "piston5_shaft_visual" >
			<origin xyz = "0 0 0" rpy = "0 0 0" />
			<geometry>
				<cylinder radius = "0.05" length = "1.0325169515442627" />
			</geometry>
		</visual>

		<collision name = "piston5_shaft_collision" >
			<origin xyz = "0 0 0" rpy = "0 0 0" />
			<geometry>
				<cylinder radius = "0.05" length = "1.0325169515442627" />
			</geometry>
		</collision>
	</link>

	<link name = "piston6_shaft_link" >
		<inertial>
			<mass value = "0.1" />
			<origin xyz = "0 0 0" rpy = "0 0 0" />
			<inertia ixx = "0.0"
					 ixy = "0.0"
					 ixz = "0.0"
					 iyy = "0.0"
					 iyz = "0.0"
					 izz = "0.0" />
		</inertial>

		<visual name = "piston6_shaft_visual" >
			<origin xyz = "0 0 0" rpy = "0 0 0" />
			<geometry>
				<cylinder radius = "0.05" length = "1.0325169515442627" />
			</geometry>
		</visual>

		<collision name = "piston6_shaft_collision" >
			<origin xyz = "0 0 0" rpy = "0 0 0" />
			<geometry>
				<cylinder radius = "0.05" length = "1.0325169515442627" />
			</geometry>
		</collision>
	</link>

	<gazebo>
	  <static> false </static>

	  <plugin name="gazebo_ros_control" filename="libgazebo_ros_control.so">
	    <robotNamespace> /stewart </robotNamespace>
	  </plugin>
	</gazebo>
</robot>